Workbook

Sheet 財審様式
A1: ２０１９年度 財審様式フォーム
A3: 様式 番号 | B3: 様式名称 | M3: 摘 要
A4: 事業会計関連様式 | C4: 協議 | E4: 審議 | G4: 修正 | I4: 補正 | K4: 決算
C5: デ | D5: 紙 | E5: デ | F5: 紙 | G5: デ | H5: 紙 | I5: デ | J5: 紙 | K5: デ | L5: 紙 | M5: ※議案上程に必要な資料 デ＝デジタル資料 紙＝紙資料
B6: 事業計画書・事業報告書（議案書） | C6: ◎ | D6: － | E6: ◎ | F6: ◎ | G6: ◎ | H6: ◎ | I6: ◎ | J6: ◎ | K6: ◎ | L6: ◎ | M6: ※◎＝必要 ○＝条件または事業により必要
B7: 財審様式（本シート） | C7: ◎ | D7: － | E7: ◎ | F7: ◎ | G7: ◎ | H7: ◎ | I7: ◎ | J7: ◎ | K7: ◎ | L7: ◎ | M7: ●＝押印済み原本が必要
A8: 様式1 | B8: 委員会年間事業予算管理表 | C8: ◎ | D8: － | E8: ◎ | F8: ◎ | G8: ◎ | H8: ◎ | I8: ◎ | J8: ◎ | K8: － | L8: －
A9: 様式2 | B9: 事業費（仮）決定通知書 | C9: ◎ | D9: － | E9: ◎ | F9: ◎ | G9: ◎ | H9: ◎ | I9: ◎ | J9: ◎ | K9: － | L9: － | M9: 事業費を使用しない場合は、作成不要
A10: 様式3 | B10: 収支予算書 | C10: ◎ | D10: － | E10: ◎ | F10: ◎ | G10: － | H10: － | I10: － | J10: － | K10: － | L10: －
A11: 様式4 | B11: 収益費用明細書 | C11: ◎ | D11: － | E11: ◎ | F11: ◎ | G11: － | H11: － | I11: － | J11: － | K11: － | L11: －
A12: 様式5 | B12: 見積（請求）企業一覧表 | C12: ◎ | D12: － | E12: ◎ | F12: ◎ | G12: ◎ | H12: ◎ | I12: ◎ | J12: ◎ | K12: ◎ | L12: ◎ | M12: 計画時には見積書をリンクする 決算時には請求書及び振込受付書をリンクする
A13: 様式6 | B13: 講師等出演依頼承諾書 | C13: ○ | D13: － | E13: ○ | F13: ● | G13: ○ | H13: ● | I13: － | J13: － | K13: ○ | L13: ○ | M13: 講演等を依頼する場合に必要、規則審査会議と共通書式 決算時には請求書と同じ扱いになります。
A14: 様式7 | B14: 報酬明細書 | C14: ○ | D14: － | E14: ○ | F14: ○ | G14: ○ | H14: ○ | I14: ○ | J14: ○ | K14: － | L14: － | M14: 源泉徴収が発生する場合に必要
A15: 様式8 | B15: 協賛物品内訳書 | C15: ○ | D15: － | E15: ○ | F15: ○ | G15: ○ | H15: ○ | I15: ○ | J15: ○ | K15: － | L15: － | M15: 協賛金等導入の場合に必要
A16: 様式9 | B16: 協賛に関する覚書 | C16: ○ | D16: － | E16: ○ | F16: ○ | G16: ○ | H16: ○ | I16: ○ | J16: ○ | K16: － | L16: － | M16: 押印してある紙資料を提出
A17: 様式10 | B17: 収支決算報告書 | C17: － | D17: － | E17: － | F17: － | G17: － | H17: － | I17: － | J17: － | K17: ◎ | L17: ◎
A18: 様式11 | B18: 収益費用明細書（決算用） | C18: － | D18: － | E18: － | F18: － | G18: － | H18: － | I18: － | J18: － | K18: ◎ | L18: ◎
A19: 様式12 | B19: 差異発生理由書 | C19: － | D19: － | E19: － | F19: － | G19: ◎ | H19: ◎ | I19: ◎ | J19: ◎ | K19: ○ | L19: ○ | M19: 事業終了後、事業支払申請関連様式と請求書を事務局に提出
A20: 様式13 | B20: 消費税等計算シート | C20: － | D20: － | E20: － | F20: － | G20: － | H20: － | I20: － | J20: － | K20: ◎ | L20: ◎
A21: 様式14 | B21: 修正・補正収支予算書 | C21: － | D21: － | E21: － | F21: － | G21: ◎ | H21: ◎ | I21: ◎ | J21: ◎ | K21: － | L21: － | M21: 修正予算ならびに補正予算をする場合に使用
A22: 様式15 | B22: 収益費用明細書（修正・補正用） | C22: － | D22: － | E22: － | F22: － | G22: ◎ | H22: ◎ | I22: ◎ | J22: ◎ | K22: － | L22: － | M22: 修正予算ならびに補正予算をする場合に使用
A24: 特別領収書関連様式
A25: 様式21 | B25: 特別領収書作成申請書 | C25: ○ | D25: － | E25: ○ | F25: ○ | G25: ○ | H25: ○ | I25: ○ | J25: ○ | K25: － | L25: － | M25: 特別領収書の申請に使用
A26: 様式22 | B26: 特別領収書作成報告書 | C26: － | D26: － | E26: － | F26: － | G26: － | H26: － | I26: － | J26: － | K26: ○ | L26: ○ | M26: 未使用領収書、事業報告書ならびに様式10、様式11、 納品書の写しを添付し提出
A27: 様式23 | B27: 領収書管理台帳 | C27: － | D27: － | E27: － | F27: － | G27: － | H27: － | I27: － | J27: － | K27: － | L27: － | M27: 特別領収書を管理する時に使用 （領収書つづり及び特別領収書を管理する時に使用）
A29: 事業費支払申請関連様式
A30: 様式31 | B30: 事業費支払申請書 | M30: 事業終了後、様式12・34と請求書を事務局に提出
A31: 様式32 | B31: 事業費仮払申請書 | M31: 講師への支払いや海外事業でやむをえず現金が必要な時に使用
A32: 様式33 | B32: 事業費仮払精算書 | M32: 仮払いを受けたときの精算書
A33: 様式34 | B33: 事業費支払管理書
A35: 委員会会計関連様式
A36: 様式41 | B36: 預り金明細書 | M36: 預り金がある場合に使用
A37: 様式42 | B37: 総勘定元帳 | M37: 現金・預金のすべての金銭の動きを記載
A39: 地区・ブロック関連様式
A40: 様式51 | B40: 銀行口座届出書 （協議会事務局管理用） | C40: ◎ | D40: － | E40: ◎ | F40: ◎ | G40: ◎ | H40: ◎ | I40: ◎ | J40: ◎ | K40: ◎ | L40: ◎ | M40: 本会計、事業用委員会口座を作る場合に必要
A41: 様式52 | B41: 預金出納帳 | C41: － | D41: － | E41: － | F41: － | G41: － | H41: － | I41: － | J41: － | K41: ◎ | L41: ◎ | M41: 銀行預金の動きを記載
A42: 様式53 | B42: 現金出納帳 | C42: － | D42: － | E42: － | F42: － | G42: － | H42: － | I42: － | J42: － | K42: ◎ | L42: ◎ | M42: 手元現金の動きを記載
A43: 様式54 | B43: 源泉所得税納付報告書 | C43: － | D43: － | E43: － | F43: － | G43: － | H43: － | I43: － | J43: － | K43: ◎ | L43: ◎ | M43: 源泉所得税納付後日本ＪＣへ報告する際に必要
A44: 様式55 | B44: 銀行口座管理台帳 （協議会管理用、日本JC提出用） | C44: 協議会で作った全ての銀行口座を管理する為に、協議会の財政担当者が記入・提出
A46: 参考資料
...

Sheet 委員会年間事業予算管理表(様式1)
N1: ［ 様式1 ］
N2: 44537
N3: ver.3
B4: 一般社団法人 佐賀青年会議所
B7: 専務理事 渡邉 雅夫 | J7: 殿
M8: 一般社団法人 佐賀青年会議所
M9: ビジネス・防災対策委員会（仮）
M10: 委員長 飯笹 壽久 | N10: 印
J12: 委員会年間事業予算管理表
B13: 委員会年間総事業費 | J13: ￥ | K13: 300000
B14: 年間事業繰入金予定額 | J14: ￥ | K14: 300000
J15: ※ 年当初予算を記載し、基本的には変更しないこと。
B16: 事業開始日 | F16: 事業終了日 | J16: 事 業 名 称 | L16: 事業繰入金予定額 （財審議長 記入欄） | M16: 外部資金予定額 （登録料等） | N16: 収益計 （事業繰入金＋外部資金予定額）
B17: 1 | C17: 月 | D17: 17 | E17: 日 | F17: 1 | G17: 月 | H17: 17 | I17: 日 | J17: ２０２２年度新年会 | L17: 144000 | N17: =$L$17 -> 144000
F18: 合 計 | L18: 144000 | M18: 0 | N18: =$L$17 -> 144000

Sheet 収支予算書(様式3)
F1: [様式3]
B2: 事 業 計 画 収 支 予 算 書
B4: 事業名称：２０２２年度新年会
F5: （単位 ： 円）
B6: 項 目 | C6: 予 算 額 | D6: 前年度予算額 | E6: 前年度決算額 | F6: 摘 要
B7: （収 益 の 部）
A8: 1 | B8: 登 録 料 収 益
A9: 2 | B9: 寄 付 金 収 益
A10: 3 | B10: 補 助 金
A11: 4 | B11: 助 成 金
A12: 5 | B12: 広 告 料 収 益
A13: 6 | B13: 販 売 収 益
A14: 7 | B14: 事 業 繰 入 金 | C14: ='収益・費用明細書(様式4)'!$G$26 -> 144000 | D14: 102000 | E14: 26,328 | F14: 委員会事業費より
A15: 8 | B15: 雑 収 益
B16: 収益計 | C16: =C14 -> 144000 | D16: =D14 -> 102000 | E16: =E14 -> 26,328
B17: （費用の部）
A18: 1 | B18: 会場設営費 | C18: ='収益・費用明細書(様式4)'!$G$15 -> 61776 | D18: 12,100 | F18: 会場費
A19: 2 | B19: 企画・演出費 | C19: ='収益・費用明細書(様式4)'!$G$18 -> 31650 | D19: 41050 | F19: ミュージカル、横断幕等
A20: 3 | B20: 本部団関係費
A21: 4 | B21: 講師関係費
A22: 5 | B22: 広報費
A23: 6 | B23: 資料作成費
A24: 7 | B24: 報告書作成費
A25: 8 | B25: 渉外費
A26: 9 | B26: 旅費交通費
A27: 10 | B27: 参加記念品費
A28: 11 | B28: 保険料
A29: 12 | B29: 通信費 | C29: ='収益・費用明細書(様式4)'!$G$23 -> 48597 | D29: 45672 | E29: 26328 | F29: 案内状印刷等
A30: 13 | B30: 雑費 | D30: 550
A31: 14 | B31: 予備費 | C31: ='収益・費用明細書(様式4)'!$G$25 -> 1977 | D31: 2628 | F31: ='収益・費用明細書(様式4)'!$F$24 -> 0.013729167
B32: 支出計 | C32: ='収益・費用明細書(様式4)'!$G$26 -> 144000 | D32: 102000 | E32: =E29 -> 26328
B33: 収支差額 | C33: 0 | D33: 0 | E33: 0

Sheet 収益・費用明細書(様式4)
D1: [様式4]
B2: 事業名称：２０２２年度新年会
A4: （ 収 益 明 細 書 ） | H4: （単位：円）
A5: 科 目 | E5: 摘 要 | G5: 金 額 | H5: Ｎｏ
A6: ( | B6: 7 | C6: ) | D6: 事 業 繰 入 金 | E6: 委員会事業費より | G6: =$G$26 -> 144000
A7: 合 計 | G7: =$G$26 -> 144000
A11: （ 費 用 明 細 書 ） | H11: （単位：円）
A12: 科 目 | E12: 細 目 | F12: 摘 要 | G12: 金 額 | H12: Ｎｏ
A13: ( | B13: 1 | C13: ) | D13: 会場設営費 | E13: 会場費 | F13: 新年会会場 | G13: 55000 | H13: 1
E14: 会場費 | F14: 控室 | G14: 6776 | H14: 1
F15: 小 計 | G15: =(G13+G14) -> 61776
A16: ( | B16: 2 | C16: ) | D16: 企画・演出費 | E16: 演出費 | F16: 横断幕、スクリーン | G16: 1650 | H16: 1
E17: 演出費 | F17: ティーンズミュージカル佐賀 | G17: 30000 | H17: 3
F18: 小 計 | G18: 31650
A19: ( | B19: 12 | C19: ) | D19: 通信費 | F19: 案内状一式（返信ハガキ・封筒含む） ５５枚 | G19: 20625 | H19: 1
F20: お礼状一式（封筒含む） ５５枚 | G20: 16500 | H20: 1
F21: 案内状切手料 ９４円×５１枚 返信ハガキ切手料 ６３円×５１枚 | G21: 8007 | H21: 2
F22: お礼状切手料 ５５名×６３円 | G22: 3465
F23: 小 計 | G23: =(G19+G20+G21+G22) -> 48597
A24: ( | B24: 15 | C24: ) | D24: 予備費 | F24: =(G24/G26) -> 0.013729167 | G24: 1977
F25: 小 計 | G25: =(G24) -> 1977
F26: 合 計 | G26: =(G15+G18+G23+G25) -> 144000

Sheet 見積企業一覧表(様式5)
H1: 〔様式5〕
B2: 見積（請求）企業一覧表
B3: （ 事業名称 ：２０２２年度新年会）
A5: 採 用 企 業 | F5: 相 見 積 企 業
A6: 見積/請求№ | B6: 企 業 名 | C6: 支払内容（科目・細目） | D6: 金 額 | E6: 有効期限 | F6: 見積№ | G6: 企 業 名 | H6: 金額
A7: 1 | B7: グランデはがくれ | C7: 会場費・通信費等 | D7: 100551 | E7: 44592
A8: 2 | B8: ローソン | C8: 通信費 | D8: 8007 | E8: 44553
A9: 3 | B9: ティーンズミュージカルＳＡＧＡ | C9: 演出費 | D9: 30000 | E9: 44926
C10: 合計金額 | D10: =(D7+D9+D8) -> 138558
A11: ※支払先が個人の場合は個人名を企業名欄に記載し、金額欄は源泉税込みの金額を記載すること。
A12: ※見積書へ見積Ｎｏ．をまたは請求書へ請求Ｎｏ．を記載すること。
A13: ※採用企業合計＋振込手数料＋予備費＝事業費合計になることを確認下さい。
A16: 見積/請求№ | B16: 振込口座名義 | C16: 支払銀行・支店名 | D16: 口座番号 | E16: 振込手数料
A17: 1 | B17: 公立学校共済組合佐賀宿泊所グランデはがくれ | C17: 佐賀銀行本店 | D17: 普通７９９３９７ | E17: 現金支払い
A18: 3 | B18: 株式会社 スタジオ風のたね | C18: 佐賀銀行本店 | D18: 普通３０２８１３７ | E18: 現金支払い
D19: 合計金額 | E19: 0
